Workbook

Sheet 01_Raw_Inputs
A1: This tab is not read by the model! The model reads the "03_Calculated_Costs" tab. Here, you can put the raw costs as they are depicted in the respective sources and then adjust them using "02_Parameters" to have uniform values in "03_Calculated_Costs".
A2: Energy Perspectives 2050+ | B2: NEXUS-E | C2: Mellot et al. 2024 | D2: Based on HSLU | E2: Other | F2: SFOE
A3: technology | B3: year | C3: efficiency (storage -> grid) | D3: efficiency grid -> storage | E3: emission factor | F3: O&M Annual [CHF/MW/y] | G3: Fuel cost [CHF/MWh] | H3: Investment costs [CHF/MW] | I3: Investment costs charging facility [CHF/MW] | J3: Investment energy costs [CHF/MWh] | K3: Investment fuel storage costs [CHF/MWh_th] | L3: O&M Prod [CHF/MWh_el] | M3: amortization years
A4: battery | B4: 2035 | C4: =SQRT(0.86) -> 0.92736185 | D4: =SQRT(0.86) -> 0.92736185 | F4: 126 | H4: 43606 | J4: 51581 | L4: 0.1 | M4: 10
A5: battery | B5: 2050 | C5: =SQRT(0.86) -> 0.92736185 | D5: =SQRT(0.86) -> 0.92736185 | F5: 126 | H5: 37378 | J5: 44212 | L5: 0.1 | M5: 10
A6: biomass | B6: 2035 | C6: 0.45 | E6: 0 | G6: 37
A7: biomass | B7: 2050 | C7: 0.45 | E7: 0 | G7: 44
A8: CCGTCCS | B8: 2035 | C8: 0.47 | E8: 0.0201 | F8: 24.19 | G8: 26 | H8: 1410360 | L8: 5.42 | M8: 25
A9: CCGTCCS | B9: 2050 | C9: 0.47 | E9: 0.0201 | F9: 24.19 | G9: 18 | H9: 1410360 | L9: 5.42 | M9: 25
A10: CCGTresmethane | B10: 2035 | C10: 0.53 | E10: 0 | F10: 14.21 | G10: =55*3.6 -> 198 | H10: 650940 | L10: 4.34 | M10: 25
A11: CCGTresmethane | B11: 2050 | C11: 0.53 | E11: 0 | F11: 14.21 | G11: =55*3.6 -> 198 | H11: 650940 | L11: 4.34 | M11: 25
A12: co2 | B12: 2035 | G12: 86.5
A13: co2 | B13: 2050 | G13: 397
A14: dam | B14: 2035 | C14: 1 | D14: 1
A15: dam | B15: 2050 | C15: 1 | D15: 1
A16: dsr | B16: 2035 | C16: 1 | L16: 0.1
A17: dsr | B17: 2050 | C17: 1 | L17: 0.1
A18: dsrTh | B18: 2035 | C18: 1 | L18: 0.1
A19: dsrTh | B19: 2050 | C19: 1 | L19: 0.1
A20: electrolyzer | B20: 2035 | C20: 1
A21: electrolyzer | B21: 2050 | C21: 1
A22: ev_flex | B22: 2035 | C22: 1
A23: ev_flex | B23: 2050 | C23: 1
A24: fossilmethane | B24: 2035 | K24: 291
A25: fossilmethane | B25: 2050 | K25: 291
A26: gas | B26: 2035 | C26: =AVERAGE(C8,C10,C56,C58) -> 0.425 | E26: 0.0201 | G26: 26 | L26: =AVERAGE(L8,L10,L56,L58) -> 5.15
A27: gas | B27: 2050 | C27: =AVERAGE(C9,C11,C57,C59) -> 0.425 | E27: 0.0201 | G27: 18 | L27: =AVERAGE(L9,L11,L57,L59) -> 5.15
A28: gas_boiler | B28: 2035 | C28: 0.927 | E28: 0.2012 | F28: 9335 | G28: 26 | H28: 171780 | M28: 20
A29: gas_boiler | B29: 2050 | C29: 0.927 | E29: 0.2012 | F29: 9335 | G29: 18 | H29: 171780 | M29: 20
A30: hardcoal | B30: 2035 | C30: 0.46 | E30: 0.3337 | G30: 9 | L30: =AVERAGE(16.7,16.7,16.7,5) -> 13.775
A31: hardcoal | B31: 2050 | C31: 0.46 | E31: 0.3337 | G31: 6 | L31: =AVERAGE(16.7,16.7,16.7,5) -> 13.775
A32: heat_pump | B32: 2035 | C32: 1 | F32: 21089 | H32: 702200 | L32: 0.1 | M32: 20
A33: heat_pump | B33: 2050 | C33: 1 | F33: 21089 | H33: 702200 | L33: 0.1 | M33: 20
A34: heat_pump_households | B34: 2035 | C34: 1 | L34: 0.1
A35: heat_pump_households | B35: 2050 | C35: 1 | L35: 0.1
A36: hydrogen | B36: 2035 | C36: 0.53 | D36: =0.4/C36 -> 0.75471698 | F36: 13690 | H36: =H10*1.1 -> 716034 | I36: 1482500 | J36: =291*5 -> 1455 | M36: 15
A37: hydrogen | B37: 2050 | C37: 0.53 | D37: =0.4/C37 -> 0.75471698 | F37: 13690 | H37: =H11*1.1 -> 716034 | I37: 1113000 | J37: =291*5 -> 1455 | M37: 15
A38: nuclear | B38: 2035 | C38: 0.33 | E38: 0 | G38: 0 | H38: 10600000 | L38: 10.8 | M38: 50
A39: nuclear | B39: 2050 | C39: 0.33 | E39: 0 | G39: 0 | H39: 10600000 | L39: 10.8 | M39: 50
A40: oil | B40: 2035 | C40: 0.39 | E40: 0.2639 | G40: 49 | H40: =H56 -> 433960 | K40: 1.48 | L40: =L56 -> 5.42 | M40: =M56 -> 25
...

Sheet 02_Parameters
A1: Share of fixed operation and maintenance costs
A2: 1.025
A4: Unit conversions
A5: EUR2017toCHF2017 | B5: 1.1119
A6: EUR2024toCHF2017 | B6: 0.8889
A7: USD2017toCHF2017 | B7: 0.9843
A8: USD2024toCHF2017 | B8: 0.8148
A9: EUR2018toCHF2017 | B9: 1.1435
A10: CHF2020toCHF2017 | B10: 0.981

Sheet 03_Calculated_Costs
A1: technology | B1: year | C1: efficiency | D1: efficiency_into_storage | E1: emission_factor | F1: fixed_op_cost_chfMW | G1: input_cost_scenario_ZERO | H1: investment_cost_chfMW | I1: investment_cost_charge_chfMW | J1: investment_energy_cost_chfMWh | K1: investment_fuel_energy_cost_chfMWh | L1: om_cost_eurMWH | M1: amortization_years
A2: ='01_Raw_Inputs'!A4 -> battery | B2: ='01_Raw_Inputs'!B4 -> 2035 | C2: =ROUND('01_Raw_Inputs'!C4,4) -> 0.9274 | D2: =ROUND('01_Raw_Inputs'!D4,4) -> 0.9274 | E2: =ROUND('01_Raw_Inputs'!E4,4) -> 0 | F2: =ROUND('01_Raw_Inputs'!F4*'02_Parameters'!$B$5,4) -> 140.0994 | G2: =ROUND('01_Raw_Inputs'!G4,4) -> 0 | H2: =ROUND('01_Raw_Inputs'!H4,4) -> 43606 | I2: =ROUND('01_Raw_Inputs'!I4,4) -> 0 | J2: =ROUND('01_Raw_Inputs'!J4,4) -> 51581 | K2: =ROUND('01_Raw_Inputs'!K4,4) -> 0 | L2: =ROUND('01_Raw_Inputs'!L4,4) -> 0.1 | M2: =ROUND('01_Raw_Inputs'!M4,4) -> 10
A3: ='01_Raw_Inputs'!A5 -> battery | B3: ='01_Raw_Inputs'!B5 -> 2050 | C3: =ROUND('01_Raw_Inputs'!C5,4) -> 0.9274 | D3: =ROUND('01_Raw_Inputs'!D5,4) -> 0.9274 | E3: =ROUND('01_Raw_Inputs'!E5,4) -> 0 | F3: =ROUND('01_Raw_Inputs'!F5*'02_Parameters'!$B$5,4) -> 140.0994 | G3: =ROUND('01_Raw_Inputs'!G5,4) -> 0 | H3: =ROUND('01_Raw_Inputs'!H5,4) -> 37378 | I3: =ROUND('01_Raw_Inputs'!I5,4) -> 0 | J3: =ROUND('01_Raw_Inputs'!J5,4) -> 44212 | K3: =ROUND('01_Raw_Inputs'!K5,4) -> 0 | L3: =ROUND('01_Raw_Inputs'!L5,4) -> 0.1 | M3: =ROUND('01_Raw_Inputs'!M5,4) -> 10
A4: ='01_Raw_Inputs'!A6 -> biomass | B4: ='01_Raw_Inputs'!B6 -> 2035 | C4: =ROUND('01_Raw_Inputs'!C6,4) -> 0.45 | D4: =ROUND('01_Raw_Inputs'!D6,4) -> 0 | E4: =ROUND('01_Raw_Inputs'!E6,4) -> 0 | F4: =ROUND('01_Raw_Inputs'!F6,4) -> 0 | G4: =ROUND('01_Raw_Inputs'!G6,4) -> 37 | H4: =ROUND('01_Raw_Inputs'!H6,4) -> 0 | I4: =ROUND('01_Raw_Inputs'!I6,4) -> 0 | J4: =ROUND('01_Raw_Inputs'!J6,4) -> 0 | ... M4: =ROUND('01_Raw_Inputs'!M6,4) -> 0
A5: ='01_Raw_Inputs'!A7 -> biomass | B5: ='01_Raw_Inputs'!B7 -> 2050 | C5: =ROUND('01_Raw_Inputs'!C7,4) -> 0.45 | D5: =ROUND('01_Raw_Inputs'!D7,4) -> 0 | E5: =ROUND('01_Raw_Inputs'!E7,4) -> 0 | F5: =ROUND('01_Raw_Inputs'!F7,4) -> 0 | G5: =ROUND('01_Raw_Inputs'!G7,4) -> 44 | H5: =ROUND('01_Raw_Inputs'!H7,4) -> 0 | I5: =ROUND('01_Raw_Inputs'!I7,4) -> 0 | J5: =ROUND('01_Raw_Inputs'!J7,4) -> 0 | ... M5: =ROUND('01_Raw_Inputs'!M7,4) -> 0
A6: ='01_Raw_Inputs'!A8 -> CCGTCCS | B6: ='01_Raw_Inputs'!B8 -> 2035 | C6: =ROUND('01_Raw_Inputs'!C8,4) -> 0.47 | D6: =ROUND('01_Raw_Inputs'!D8,4) -> 0 | E6: =ROUND('01_Raw_Inputs'!E8,4) -> 0.0201 | F6: =ROUND('01_Raw_Inputs'!F8*'02_Parameters'!$B$5,4) -> 26.8969 | G6: =ROUND('01_Raw_Inputs'!G8*'02_Parameters'!$B$7,4) -> 25.5918 | H6: =ROUND('01_Raw_Inputs'!H8*'02_Parameters'!$B$5,4) -> 1568179.3 | I6: =ROUND('01_Raw_Inputs'!I8,4) -> 0 | J6: =ROUND('01_Raw_Inputs'!J8,4) -> 0 | K6: =ROUND('01_Raw_Inputs'!K8,4) -> 0 | L6: =ROUND('01_Raw_Inputs'!L8*'02_Parameters'!$B$5,4) -> 6.0265 | M6: =ROUND('01_Raw_Inputs'!M8,4) -> 25
A7: ='01_Raw_Inputs'!A9 -> CCGTCCS | B7: ='01_Raw_Inputs'!B9 -> 2050 | C7: =ROUND('01_Raw_Inputs'!C9,4) -> 0.47 | D7: =ROUND('01_Raw_Inputs'!D9,4) -> 0 | E7: =ROUND('01_Raw_Inputs'!E9,4) -> 0.0201 | F7: =ROUND('01_Raw_Inputs'!F9*'02_Parameters'!$B$5,4) -> 26.8969 | G7: =ROUND('01_Raw_Inputs'!G9*'02_Parameters'!$B$7,4) -> 17.7174 | H7: =ROUND('01_Raw_Inputs'!H9*'02_Parameters'!$B$5,4) -> 1568179.3 | I7: =ROUND('01_Raw_Inputs'!I9,4) -> 0 | J7: =ROUND('01_Raw_Inputs'!J9,4) -> 0 | K7: =ROUND('01_Raw_Inputs'!K9,4) -> 0 | L7: =ROUND('01_Raw_Inputs'!L9*'02_Parameters'!$B$5,4) -> 6.0265 | M7: =ROUND('01_Raw_Inputs'!M9,4) -> 25
A8: ='01_Raw_Inputs'!A10 -> CCGTresmethane | B8: ='01_Raw_Inputs'!B10 -> 2035 | C8: =ROUND('01_Raw_Inputs'!C10,4) -> 0.53 | D8: =ROUND('01_Raw_Inputs'!D10,4) -> 0 | E8: =ROUND('01_Raw_Inputs'!E10,4) -> 0 | F8: =ROUND('01_Raw_Inputs'!F10*'02_Parameters'!$B$5,4) -> 15.8001 | G8: =ROUND('01_Raw_Inputs'!G10*'02_Parameters'!$B$5,4) -> 220.1562 | H8: =ROUND('01_Raw_Inputs'!H10*'02_Parameters'!$B$5,4) -> 723780.19 | I8: =ROUND('01_Raw_Inputs'!I10,4) -> 0 | J8: =ROUND('01_Raw_Inputs'!J10,4) -> 0 | K8: =ROUND('01_Raw_Inputs'!K10,4) -> 0 | L8: =ROUND('01_Raw_Inputs'!L10*'02_Parameters'!$B$5,4) -> 4.8256 | M8: =ROUND('01_Raw_Inputs'!M10,4) -> 25
A9: ='01_Raw_Inputs'!A11 -> CCGTresmethane | B9: ='01_Raw_Inputs'!B11 -> 2050 | C9: =ROUND('01_Raw_Inputs'!C11,4) -> 0.53 | D9: =ROUND('01_Raw_Inputs'!D11,4) -> 0 | E9: =ROUND('01_Raw_Inputs'!E11,4) -> 0 | F9: =ROUND('01_Raw_Inputs'!F11*'02_Parameters'!$B$5,4) -> 15.8001 | G9: =ROUND('01_Raw_Inputs'!G11*'02_Parameters'!$B$5,4) -> 220.1562 | H9: =ROUND('01_Raw_Inputs'!H11*'02_Parameters'!$B$5,4) -> 723780.19 | I9: =ROUND('01_Raw_Inputs'!I11,4) -> 0 | J9: =ROUND('01_Raw_Inputs'!J11,4) -> 0 | K9: =ROUND('01_Raw_Inputs'!K11,4) -> 0 | L9: =ROUND('01_Raw_Inputs'!L11*'02_Parameters'!$B$5,4) -> 4.8256 | M9: =ROUND('01_Raw_Inputs'!M11,4) -> 25
A10: ='01_Raw_Inputs'!A12 -> co2 | B10: ='01_Raw_Inputs'!B12 -> 2035 | C10: =ROUND('01_Raw_Inputs'!C12,4) -> 0 | D10: =ROUND('01_Raw_Inputs'!D12,4) -> 0 | E10: =ROUND('01_Raw_Inputs'!E12,4) -> 0 | F10: =ROUND('01_Raw_Inputs'!F12,4) -> 0 | G10: =ROUND('01_Raw_Inputs'!G12*'02_Parameters'!$B$7,4) -> 85.142 | H10: =ROUND('01_Raw_Inputs'!H12,4) -> 0 | I10: =ROUND('01_Raw_Inputs'!I12,4) -> 0 | J10: =ROUND('01_Raw_Inputs'!J12,4) -> 0 | K10: =ROUND('01_Raw_Inputs'!K12,4) -> 0 | L10: =ROUND('01_Raw_Inputs'!L12,4) -> 0 | M10: =ROUND('01_Raw_Inputs'!M12,4) -> 0
A11: ='01_Raw_Inputs'!A13 -> co2 | B11: ='01_Raw_Inputs'!B13 -> 2050 | C11: =ROUND('01_Raw_Inputs'!C13,4) -> 0 | D11: =ROUND('01_Raw_Inputs'!D13,4) -> 0 | E11: =ROUND('01_Raw_Inputs'!E13,4) -> 0 | F11: =ROUND('01_Raw_Inputs'!F13,4) -> 0 | G11: =ROUND('01_Raw_Inputs'!G13*'02_Parameters'!$B$7,4) -> 390.7671 | H11: =ROUND('01_Raw_Inputs'!H13,4) -> 0 | I11: =ROUND('01_Raw_Inputs'!I13,4) -> 0 | J11: =ROUND('01_Raw_Inputs'!J13,4) -> 0 | K11: =ROUND('01_Raw_Inputs'!K13,4) -> 0 | L11: =ROUND('01_Raw_Inputs'!L13,4) -> 0 | M11: =ROUND('01_Raw_Inputs'!M13,4) -> 0
A12: ='01_Raw_Inputs'!A14 -> dam | B12: ='01_Raw_Inputs'!B14 -> 2035 | C12: =ROUND('01_Raw_Inputs'!C14,4) -> 1 | D12: =ROUND('01_Raw_Inputs'!D14,4) -> 1 | E12: =ROUND('01_Raw_Inputs'!E14,4) -> 0 | F12: =ROUND('01_Raw_Inputs'!F14,4) -> 0 | G12: =ROUND('01_Raw_Inputs'!G14,4) -> 0 | H12: =ROUND('01_Raw_Inputs'!H14,4) -> 0 | I12: =ROUND('01_Raw_Inputs'!I14,4) -> 0 | J12: =ROUND('01_Raw_Inputs'!J14,4) -> 0 | ... M12: =ROUND('01_Raw_Inputs'!M14,4) -> 0
A13: ='01_Raw_Inputs'!A15 -> dam | B13: ='01_Raw_Inputs'!B15 -> 2050 | C13: =ROUND('01_Raw_Inputs'!C15,4) -> 1 | D13: =ROUND('01_Raw_Inputs'!D15,4) -> 1 | E13: =ROUND('01_Raw_Inputs'!E15,4) -> 0 | F13: =ROUND('01_Raw_Inputs'!F15,4) -> 0 | G13: =ROUND('01_Raw_Inputs'!G15,4) -> 0 | H13: =ROUND('01_Raw_Inputs'!H15,4) -> 0 | I13: =ROUND('01_Raw_Inputs'!I15,4) -> 0 | J13: =ROUND('01_Raw_Inputs'!J15,4) -> 0 | ... M13: =ROUND('01_Raw_Inputs'!M15,4) -> 0
A14: ='01_Raw_Inputs'!A16 -> dsr | B14: ='01_Raw_Inputs'!B16 -> 2035 | C14: =ROUND('01_Raw_Inputs'!C16,4) -> 1 | D14: =ROUND('01_Raw_Inputs'!D16,4) -> 0 | E14: =ROUND('01_Raw_Inputs'!E16,4) -> 0 | F14: =ROUND('01_Raw_Inputs'!F16,4) -> 0 | G14: =ROUND('01_Raw_Inputs'!G16,4) -> 0 | H14: =ROUND('01_Raw_Inputs'!H16,4) -> 0 | I14: =ROUND('01_Raw_Inputs'!I16,4) -> 0 | J14: =ROUND('01_Raw_Inputs'!J16,4) -> 0 | ... M14: =ROUND('01_Raw_Inputs'!M16,4) -> 0
A15: ='01_Raw_Inputs'!A17 -> dsr | B15: ='01_Raw_Inputs'!B17 -> 2050 | C15: =ROUND('01_Raw_Inputs'!C17,4) -> 1 | D15: =ROUND('01_Raw_Inputs'!D17,4) -> 0 | E15: =ROUND('01_Raw_Inputs'!E17,4) -> 0 | F15: =ROUND('01_Raw_Inputs'!F17,4) -> 0 | G15: =ROUND('01_Raw_Inputs'!G17,4) -> 0 | H15: =ROUND('01_Raw_Inputs'!H17,4) -> 0 | I15: =ROUND('01_Raw_Inputs'!I17,4) -> 0 | J15: =ROUND('01_Raw_Inputs'!J17,4) -> 0 | ... M15: =ROUND('01_Raw_Inputs'!M17,4) -> 0
A16: ='01_Raw_Inputs'!A18 -> dsrTh | B16: ='01_Raw_Inputs'!B18 -> 2035 | C16: =ROUND('01_Raw_Inputs'!C18,4) -> 1 | D16: =ROUND('01_Raw_Inputs'!D18,4) -> 0 | E16: =ROUND('01_Raw_Inputs'!E18,4) -> 0 | F16: =ROUND('01_Raw_Inputs'!F18,4) -> 0 | G16: =ROUND('01_Raw_Inputs'!G18,4) -> 0 | H16: =ROUND('01_Raw_Inputs'!H18,4) -> 0 | I16: =ROUND('01_Raw_Inputs'!I18,4) -> 0 | J16: =ROUND('01_Raw_Inputs'!J18,4) -> 0 | ... M16: =ROUND('01_Raw_Inputs'!M18,4) -> 0
A17: ='01_Raw_Inputs'!A19 -> dsrTh | B17: ='01_Raw_Inputs'!B19 -> 2050 | C17: =ROUND('01_Raw_Inputs'!C19,4) -> 1 | D17: =ROUND('01_Raw_Inputs'!D19,4) -> 0 | E17: =ROUND('01_Raw_Inputs'!E19,4) -> 0 | F17: =ROUND('01_Raw_Inputs'!F19,4) -> 0 | G17: =ROUND('01_Raw_Inputs'!G19,4) -> 0 | H17: =ROUND('01_Raw_Inputs'!H19,4) -> 0 | I17: =ROUND('01_Raw_Inputs'!I19,4) -> 0 | J17: =ROUND('01_Raw_Inputs'!J19,4) -> 0 | ... M17: =ROUND('01_Raw_Inputs'!M19,4) -> 0
A18: ='01_Raw_Inputs'!A20 -> electrolyzer | B18: ='01_Raw_Inputs'!B20 -> 2035 | C18: =ROUND('01_Raw_Inputs'!C20,4) -> 1 | D18: =ROUND('01_Raw_Inputs'!D20,4) -> 0 | E18: =ROUND('01_Raw_Inputs'!E20,4) -> 0 | F18: =ROUND('01_Raw_Inputs'!F20,4) -> 0 | G18: =ROUND('01_Raw_Inputs'!G20,4) -> 0 | H18: =ROUND('01_Raw_Inputs'!H20,4) -> 0 | I18: =ROUND('01_Raw_Inputs'!I20,4) -> 0 | J18: =ROUND('01_Raw_Inputs'!J20,4) -> 0 | ... M18: =ROUND('01_Raw_Inputs'!M20,4) -> 0
A19: ='01_Raw_Inputs'!A21 -> electrolyzer | B19: ='01_Raw_Inputs'!B21 -> 2050 | C19: =ROUND('01_Raw_Inputs'!C21,4) -> 1 | D19: =ROUND('01_Raw_Inputs'!D21,4) -> 0 | E19: =ROUND('01_Raw_Inputs'!E21,4) -> 0 | F19: =ROUND('01_Raw_Inputs'!F21,4) -> 0 | G19: =ROUND('01_Raw_Inputs'!G21,4) -> 0 | H19: =ROUND('01_Raw_Inputs'!H21,4) -> 0 | I19: =ROUND('01_Raw_Inputs'!I21,4) -> 0 | J19: =ROUND('01_Raw_Inputs'!J21,4) -> 0 | ... M19: =ROUND('01_Raw_Inputs'!M21,4) -> 0
A20: ='01_Raw_Inputs'!A22 -> ev_flex | B20: ='01_Raw_Inputs'!B22 -> 2035 | C20: =ROUND('01_Raw_Inputs'!C22,4) -> 1 | D20: =ROUND('01_Raw_Inputs'!D22,4) -> 0 | E20: =ROUND('01_Raw_Inputs'!E22,4) -> 0 | F20: =ROUND('01_Raw_Inputs'!F22,4) -> 0 | G20: =ROUND('01_Raw_Inputs'!G22,4) -> 0 | H20: =ROUND('01_Raw_Inputs'!H22,4) -> 0 | I20: =ROUND('01_Raw_Inputs'!I22,4) -> 0 | J20: =ROUND('01_Raw_Inputs'!J22,4) -> 0 | ... M20: =ROUND('01_Raw_Inputs'!M22,4) -> 0
A21: ='01_Raw_Inputs'!A23 -> ev_flex | B21: ='01_Raw_Inputs'!B23 -> 2050 | C21: =ROUND('01_Raw_Inputs'!C23,4) -> 1 | D21: =ROUND('01_Raw_Inputs'!D23,4) -> 0 | E21: =ROUND('01_Raw_Inputs'!E23,4) -> 0 | F21: =ROUND('01_Raw_Inputs'!F23,4) -> 0 | G21: =ROUND('01_Raw_Inputs'!G23,4) -> 0 | H21: =ROUND('01_Raw_Inputs'!H23,4) -> 0 | I21: =ROUND('01_Raw_Inputs'!I23,4) -> 0 | J21: =ROUND('01_Raw_Inputs'!J23,4) -> 0 | ... M21: =ROUND('01_Raw_Inputs'!M23,4) -> 0
A22: ='01_Raw_Inputs'!A24 -> fossilmethane | B22: ='01_Raw_Inputs'!B24 -> 2035 | C22: =ROUND('01_Raw_Inputs'!C24,4) -> 0 | D22: =ROUND('01_Raw_Inputs'!D24,4) -> 0 | E22: =ROUND('01_Raw_Inputs'!E24,4) -> 0 | F22: =ROUND('01_Raw_Inputs'!F24,4) -> 0 | G22: =ROUND('01_Raw_Inputs'!G24,4) -> 0 | H22: =ROUND('01_Raw_Inputs'!H24,4) -> 0 | I22: =ROUND('01_Raw_Inputs'!I24,4) -> 0 | J22: =ROUND('01_Raw_Inputs'!J24,4) -> 0 | K22: =ROUND('01_Raw_Inputs'!K24*'02_Parameters'!$B$10,4) -> 285.471 | L22: =ROUND('01_Raw_Inputs'!L24,4) -> 0 | M22: =ROUND('01_Raw_Inputs'!M24,4) -> 0
A23: ='01_Raw_Inputs'!A25 -> fossilmethane | B23: ='01_Raw_Inputs'!B25 -> 2050 | C23: =ROUND('01_Raw_Inputs'!C25,4) -> 0 | D23: =ROUND('01_Raw_Inputs'!D25,4) -> 0 | E23: =ROUND('01_Raw_Inputs'!E25,4) -> 0 | F23: =ROUND('01_Raw_Inputs'!F25,4) -> 0 | G23: =ROUND('01_Raw_Inputs'!G25,4) -> 0 | H23: =ROUND('01_Raw_Inputs'!H25,4) -> 0 | I23: =ROUND('01_Raw_Inputs'!I25,4) -> 0 | J23: =ROUND('01_Raw_Inputs'!J25,4) -> 0 | K23: =ROUND('01_Raw_Inputs'!K25*'02_Parameters'!$B$10,4) -> 285.471 | L23: =ROUND('01_Raw_Inputs'!L25,4) -> 0 | M23: =ROUND('01_Raw_Inputs'!M25,4) -> 0
A24: ='01_Raw_Inputs'!A26 -> gas | B24: ='01_Raw_Inputs'!B26 -> 2035 | C24: =ROUND('01_Raw_Inputs'!C26,4) -> 0.425 | D24: =ROUND('01_Raw_Inputs'!D26,4) -> 0 | E24: =ROUND('01_Raw_Inputs'!E26,4) -> 0.0201 | F24: =ROUND('01_Raw_Inputs'!F26,4) -> 0 | G24: =ROUND('01_Raw_Inputs'!G26*'02_Parameters'!$B$7,4) -> 25.5918 | H24: =ROUND('01_Raw_Inputs'!H26,4) -> 0 | I24: =ROUND('01_Raw_Inputs'!I26,4) -> 0 | J24: =ROUND('01_Raw_Inputs'!J26,4) -> 0 | K24: =ROUND('01_Raw_Inputs'!K26,4) -> 0 | L24: =ROUND('01_Raw_Inputs'!L26,4) -> 5.15 | M24: =ROUND('01_Raw_Inputs'!M26,4) -> 0
A25: ='01_Raw_Inputs'!A27 -> gas | B25: ='01_Raw_Inputs'!B27 -> 2050 | C25: =ROUND('01_Raw_Inputs'!C27,4) -> 0.425 | D25: =ROUND('01_Raw_Inputs'!D27,4) -> 0 | E25: =ROUND('01_Raw_Inputs'!E27,4) -> 0.0201 | F25: =ROUND('01_Raw_Inputs'!F27,4) -> 0 | G25: =ROUND('01_Raw_Inputs'!G27*'02_Parameters'!$B$7,4) -> 17.7174 | H25: =ROUND('01_Raw_Inputs'!H27,4) -> 0 | I25: =ROUND('01_Raw_Inputs'!I27,4) -> 0 | J25: =ROUND('01_Raw_Inputs'!J27,4) -> 0 | K25: =ROUND('01_Raw_Inputs'!K27,4) -> 0 | L25: =ROUND('01_Raw_Inputs'!L27,4) -> 5.15 | M25: =ROUND('01_Raw_Inputs'!M27,4) -> 0
A26: ='01_Raw_Inputs'!A28 -> gas_boiler | B26: ='01_Raw_Inputs'!B28 -> 2035 | C26: =ROUND('01_Raw_Inputs'!C28,4) -> 0.927 | D26: =ROUND('01_Raw_Inputs'!D28,4) -> 0 | E26: =ROUND('01_Raw_Inputs'!E28,4) -> 0.2012 | F26: =ROUND('01_Raw_Inputs'!F28*'02_Parameters'!$B$5,4) -> 10379.586 | G26: =ROUND('01_Raw_Inputs'!G28*'02_Parameters'!$B$7,4) -> 25.5918 | H26: =ROUND('01_Raw_Inputs'!H28*'02_Parameters'!$B$5,4) -> 191002.18 | I26: =ROUND('01_Raw_Inputs'!I28,4) -> 0 | J26: =ROUND('01_Raw_Inputs'!J28,4) -> 0 | K26: =ROUND('01_Raw_Inputs'!K28,4) -> 0 | L26: =ROUND('01_Raw_Inputs'!L28,4) -> 0 | M26: =ROUND('01_Raw_Inputs'!M28,4) -> 20
A27: ='01_Raw_Inputs'!A29 -> gas_boiler | B27: ='01_Raw_Inputs'!B29 -> 2050 | C27: =ROUND('01_Raw_Inputs'!C29,4) -> 0.927 | D27: =ROUND('01_Raw_Inputs'!D29,4) -> 0 | E27: =ROUND('01_Raw_Inputs'!E29,4) -> 0.2012 | F27: =ROUND('01_Raw_Inputs'!F29*'02_Parameters'!$B$5,4) -> 10379.586 | G27: =ROUND('01_Raw_Inputs'!G29*'02_Parameters'!$B$7,4) -> 17.7174 | H27: =ROUND('01_Raw_Inputs'!H29*'02_Parameters'!$B$5,4) -> 191002.18 | I27: =ROUND('01_Raw_Inputs'!I29,4) -> 0 | J27: =ROUND('01_Raw_Inputs'!J29,4) -> 0 | K27: =ROUND('01_Raw_Inputs'!K29,4) -> 0 | L27: =ROUND('01_Raw_Inputs'!L29,4) -> 0 | M27: =ROUND('01_Raw_Inputs'!M29,4) -> 20
A28: ='01_Raw_Inputs'!A30 -> hardcoal | B28: ='01_Raw_Inputs'!B30 -> 2035 | C28: =ROUND('01_Raw_Inputs'!C30,4) -> 0.46 | D28: =ROUND('01_Raw_Inputs'!D30,4) -> 0 | E28: =ROUND('01_Raw_Inputs'!E30,4) -> 0.3337 | F28: =ROUND('01_Raw_Inputs'!F30,4) -> 0 | G28: =ROUND('01_Raw_Inputs'!G30*'02_Parameters'!$B$7,4) -> 8.8587 | H28: =ROUND('01_Raw_Inputs'!H30,4) -> 0 | I28: =ROUND('01_Raw_Inputs'!I30,4) -> 0 | J28: =ROUND('01_Raw_Inputs'!J30,4) -> 0 | K28: =ROUND('01_Raw_Inputs'!K30,4) -> 0 | L28: =ROUND('01_Raw_Inputs'!L30*'02_Parameters'!$B$9,4) -> 15.7517 | M28: =ROUND('01_Raw_Inputs'!M30,4) -> 0
A29: ='01_Raw_Inputs'!A31 -> hardcoal | B29: ='01_Raw_Inputs'!B31 -> 2050 | C29: =ROUND('01_Raw_Inputs'!C31,4) -> 0.46 | D29: =ROUND('01_Raw_Inputs'!D31,4) -> 0 | E29: =ROUND('01_Raw_Inputs'!E31,4) -> 0.3337 | F29: =ROUND('01_Raw_Inputs'!F31,4) -> 0 | G29: =ROUND('01_Raw_Inputs'!G31*'02_Parameters'!$B$7,4) -> 5.9058 | H29: =ROUND('01_Raw_Inputs'!H31,4) -> 0 | I29: =ROUND('01_Raw_Inputs'!I31,4) -> 0 | J29: =ROUND('01_Raw_Inputs'!J31,4) -> 0 | K29: =ROUND('01_Raw_Inputs'!K31,4) -> 0 | L29: =ROUND('01_Raw_Inputs'!L31*'02_Parameters'!$B$9,4) -> 15.7517 | M29: =ROUND('01_Raw_Inputs'!M31,4) -> 0
A30: ='01_Raw_Inputs'!A32 -> heat_pump | B30: ='01_Raw_Inputs'!B32 -> 2035 | C30: =ROUND('01_Raw_Inputs'!C32,4) -> 1 | D30: =ROUND('01_Raw_Inputs'!D32,4) -> 0 | E30: =ROUND('01_Raw_Inputs'!E32,4) -> 0 | F30: =ROUND('01_Raw_Inputs'!F32*'02_Parameters'!$B$5,4) -> 23448.859 | G30: =ROUND('01_Raw_Inputs'!G32,4) -> 0 | H30: =ROUND('01_Raw_Inputs'!H32*'02_Parameters'!$B$5,4) -> 780776.18 | I30: =ROUND('01_Raw_Inputs'!I32,4) -> 0 | J30: =ROUND('01_Raw_Inputs'!J32,4) -> 0 | K30: =ROUND('01_Raw_Inputs'!K32,4) -> 0 | L30: =ROUND('01_Raw_Inputs'!L32,4) -> 0.1 | M30: =ROUND('01_Raw_Inputs'!M32,4) -> 20
A31: ='01_Raw_Inputs'!A33 -> heat_pump | B31: ='01_Raw_Inputs'!B33 -> 2050 | C31: =ROUND('01_Raw_Inputs'!C33,4) -> 1 | D31: =ROUND('01_Raw_Inputs'!D33,4) -> 0 | E31: =ROUND('01_Raw_Inputs'!E33,4) -> 0 | F31: =ROUND('01_Raw_Inputs'!F33*'02_Parameters'!$B$5,4) -> 23448.859 | G31: =ROUND('01_Raw_Inputs'!G33,4) -> 0 | H31: =ROUND('01_Raw_Inputs'!H33*'02_Parameters'!$B$5,4) -> 780776.18 | I31: =ROUND('01_Raw_Inputs'!I33,4) -> 0 | J31: =ROUND('01_Raw_Inputs'!J33,4) -> 0 | K31: =ROUND('01_Raw_Inputs'!K33,4) -> 0 | L31: =ROUND('01_Raw_Inputs'!L33,4) -> 0.1 | M31: =ROUND('01_Raw_Inputs'!M33,4) -> 20
A32: ='01_Raw_Inputs'!A34 -> heat_pump_households | B32: ='01_Raw_Inputs'!B34 -> 2035 | C32: =ROUND('01_Raw_Inputs'!C34,4) -> 1 | D32: =ROUND('01_Raw_Inputs'!D34,4) -> 0 | E32: =ROUND('01_Raw_Inputs'!E34,4) -> 0 | F32: =ROUND('01_Raw_Inputs'!F34,4) -> 0 | G32: =ROUND('01_Raw_Inputs'!G34,4) -> 0 | H32: =ROUND('01_Raw_Inputs'!H34,4) -> 0 | I32: =ROUND('01_Raw_Inputs'!I34,4) -> 0 | J32: =ROUND('01_Raw_Inputs'!J34,4) -> 0 | ... M32: =ROUND('01_Raw_Inputs'!M34,4) -> 0
A33: ='01_Raw_Inputs'!A35 -> heat_pump_households | B33: ='01_Raw_Inputs'!B35 -> 2050 | C33: =ROUND('01_Raw_Inputs'!C35,4) -> 1 | D33: =ROUND('01_Raw_Inputs'!D35,4) -> 0 | E33: =ROUND('01_Raw_Inputs'!E35,4) -> 0 | F33: =ROUND('01_Raw_Inputs'!F35,4) -> 0 | G33: =ROUND('01_Raw_Inputs'!G35,4) -> 0 | H33: =ROUND('01_Raw_Inputs'!H35,4) -> 0 | I33: =ROUND('01_Raw_Inputs'!I35,4) -> 0 | J33: =ROUND('01_Raw_Inputs'!J35,4) -> 0 | ... M33: =ROUND('01_Raw_Inputs'!M35,4) -> 0
A34: ='01_Raw_Inputs'!A36 -> hydrogen | B34: ='01_Raw_Inputs'!B36 -> 2035 | C34: =ROUND('01_Raw_Inputs'!C36,4) -> 0.53 | D34: =ROUND('01_Raw_Inputs'!D36,4) -> 0.7547 | E34: =ROUND('01_Raw_Inputs'!E36,4) -> 0 | F34: =ROUND('01_Raw_Inputs'!F36*'02_Parameters'!$B$5,4) -> 15221.911 | G34: =ROUND('01_Raw_Inputs'!G36,4) -> 0 | H34: =ROUND('01_Raw_Inputs'!H36*'02_Parameters'!$B$5,4) -> 796158.2 | I34: =ROUND('01_Raw_Inputs'!I36*'02_Parameters'!$B$6,4) -> 1317794.2 | J34: =ROUND('01_Raw_Inputs'!J36*'02_Parameters'!$B$10,4) -> 1427.355 | K34: =ROUND('01_Raw_Inputs'!K36,4) -> 0 | L34: =ROUND('01_Raw_Inputs'!L36,4) -> 0 | M34: =ROUND('01_Raw_Inputs'!M36,4) -> 15
A35: ='01_Raw_Inputs'!A37 -> hydrogen | B35: ='01_Raw_Inputs'!B37 -> 2050 | C35: =ROUND('01_Raw_Inputs'!C37,4) -> 0.53 | D35: =ROUND('01_Raw_Inputs'!D37,4) -> 0.7547 | E35: =ROUND('01_Raw_Inputs'!E37,4) -> 0 | F35: =ROUND('01_Raw_Inputs'!F37*'02_Parameters'!$B$5,4) -> 15221.911 | G35: =ROUND('01_Raw_Inputs'!G37,4) -> 0 | H35: =ROUND('01_Raw_Inputs'!H37*'02_Parameters'!$B$5,4) -> 796158.2 | I35: =ROUND('01_Raw_Inputs'!I37*'02_Parameters'!$B$6,4) -> 989345.7 | J35: =ROUND('01_Raw_Inputs'!J37*'02_Parameters'!$B$10,4) -> 1427.355 | K35: =ROUND('01_Raw_Inputs'!K37,4) -> 0 | L35: =ROUND('01_Raw_Inputs'!L37,4) -> 0 | M35: =ROUND('01_Raw_Inputs'!M37,4) -> 15
A36: ='01_Raw_Inputs'!A38 -> nuclear | B36: ='01_Raw_Inputs'!B38 -> 2035 | C36: =ROUND('01_Raw_Inputs'!C38,4) -> 0.33 | D36: =ROUND('01_Raw_Inputs'!D38,4) -> 0 | E36: =ROUND('01_Raw_Inputs'!E38,4) -> 0 | F36: =ROUND('01_Raw_Inputs'!F38,4) -> 0 | G36: =ROUND('01_Raw_Inputs'!G38,4) -> 0 | H36: =ROUND('01_Raw_Inputs'!H38*'02_Parameters'!$B$8*'02_Parameters'!$A$2,4) -> 8852802 | I36: =ROUND('01_Raw_Inputs'!I38,4) -> 0 | J36: =ROUND('01_Raw_Inputs'!J38,4) -> 0 | K36: =ROUND('01_Raw_Inputs'!K38,4) -> 0 | L36: =ROUND('01_Raw_Inputs'!L38*'02_Parameters'!$B$9,4) -> 12.3498 | M36: =ROUND('01_Raw_Inputs'!M38,4) -> 50
A37: ='01_Raw_Inputs'!A39 -> nuclear | B37: ='01_Raw_Inputs'!B39 -> 2050 | C37: =ROUND('01_Raw_Inputs'!C39,4) -> 0.33 | D37: =ROUND('01_Raw_Inputs'!D39,4) -> 0 | E37: =ROUND('01_Raw_Inputs'!E39,4) -> 0 | F37: =ROUND('01_Raw_Inputs'!F39,4) -> 0 | G37: =ROUND('01_Raw_Inputs'!G39,4) -> 0 | H37: =ROUND('01_Raw_Inputs'!H39*'02_Parameters'!$B$8*'02_Parameters'!$A$2,4) -> 8852802 | I37: =ROUND('01_Raw_Inputs'!I39,4) -> 0 | J37: =ROUND('01_Raw_Inputs'!J39,4) -> 0 | K37: =ROUND('01_Raw_Inputs'!K39,4) -> 0 | L37: =ROUND('01_Raw_Inputs'!L39*'02_Parameters'!$B$9,4) -> 12.3498 | M37: =ROUND('01_Raw_Inputs'!M39,4) -> 50
A38: ='01_Raw_Inputs'!A40 -> oil | B38: ='01_Raw_Inputs'!B40 -> 2035 | C38: =ROUND('01_Raw_Inputs'!C40,4) -> 0.39 | D38: =ROUND('01_Raw_Inputs'!D40,4) -> 0 | E38: =ROUND('01_Raw_Inputs'!E40,4) -> 0.2639 | F38: =ROUND('01_Raw_Inputs'!F40,4) -> 0 | G38: =ROUND('01_Raw_Inputs'!G40,4) -> 49 | H38: =ROUND('01_Raw_Inputs'!H40*'02_Parameters'!$B$5,4) -> 482520.12 | I38: =ROUND('01_Raw_Inputs'!I40,4) -> 0 | J38: =ROUND('01_Raw_Inputs'!J40,4) -> 0 | K38: =ROUND('01_Raw_Inputs'!K40,4) -> 1.48 | L38: =ROUND('01_Raw_Inputs'!L40*'02_Parameters'!$B$5,4) -> 6.0265 | M38: =ROUND('01_Raw_Inputs'!M40,4) -> 25
A39: ='01_Raw_Inputs'!A41 -> oil | B39: ='01_Raw_Inputs'!B41 -> 2050 | C39: =ROUND('01_Raw_Inputs'!C41,4) -> 0.39 | D39: =ROUND('01_Raw_Inputs'!D41,4) -> 0 | E39: =ROUND('01_Raw_Inputs'!E41,4) -> 0.2639 | F39: =ROUND('01_Raw_Inputs'!F41,4) -> 0 | G39: =ROUND('01_Raw_Inputs'!G41,4) -> 30 | H39: =ROUND('01_Raw_Inputs'!H41*'02_Parameters'!$B$5,4) -> 482520.12 | I39: =ROUND('01_Raw_Inputs'!I41,4) -> 0 | J39: =ROUND('01_Raw_Inputs'!J41,4) -> 0 | K39: =ROUND('01_Raw_Inputs'!K41,4) -> 1.48 | L39: =ROUND('01_Raw_Inputs'!L41*'02_Parameters'!$B$5,4) -> 6.0265 | M39: =ROUND('01_Raw_Inputs'!M41,4) -> 25
A40: ='01_Raw_Inputs'!A42 -> other | B40: ='01_Raw_Inputs'!B42 -> 2035 | C40: =ROUND('01_Raw_Inputs'!C42,4) -> 1 | D40: =ROUND('01_Raw_Inputs'!D42,4) -> 0 | E40: =ROUND('01_Raw_Inputs'!E42,4) -> 0 | F40: =ROUND('01_Raw_Inputs'!F42,4) -> 0 | G40: =ROUND('01_Raw_Inputs'!G42,4) -> 20 | H40: =ROUND('01_Raw_Inputs'!H42,4) -> 0 | I40: =ROUND('01_Raw_Inputs'!I42,4) -> 0 | J40: =ROUND('01_Raw_Inputs'!J42,4) -> 0 | ... M40: =ROUND('01_Raw_Inputs'!M42,4) -> 0
...
